[2024-04-24T09:18:38.939+0000] {scheduler_job_runner.py:781} ERROR - Executor reports task instance <TaskInstance: use_case_dag.task_3 manual__2024-04-24T08:41:16.403808+00:00 [queued]> finished (failed) although the task says it's queued. (Info: None) Was the task killed externally?
