[2024-04-24T09:35:42.613+0000] {taskinstance.py:1979} INFO - Dependencies all met for dep_context=non-requeueable deps ti=<TaskInstance: use_case_dag.task_3 manual__2024-04-24T09:35:04.462838+00:00 [queued]>
[2024-04-24T09:35:42.629+0000] {taskinstance.py:1979} INFO - Dependencies all met for dep_context=requeueable deps ti=<TaskInstance: use_case_dag.task_3 manual__2024-04-24T09:35:04.462838+00:00 [queued]>
[2024-04-24T09:35:42.640+0000] {taskinstance.py:2193} INFO - Starting attempt 1 of 6
[2024-04-24T09:35:42.658+0000] {taskinstance.py:2217} INFO - Executing <Task(_PythonDecoratedOperator): task_3> on 2024-04-24 09:35:04.462838+00:00
[2024-04-24T09:35:42.667+0000] {standard_task_runner.py:60} INFO - Started process 8365 to run task
[2024-04-24T09:35:42.673+0000] {standard_task_runner.py:87} INFO - Running: ['***', 'tasks', 'run', 'use_case_dag', 'task_3', 'manual__2024-04-24T09:35:04.462838+00:00', '--job-id', '45', '--raw', '--subdir', 'DAGS_FOLDER/use_case_dag.py', '--cfg-path', '/tmp/tmplylju8u6']
[2024-04-24T09:35:42.679+0000] {standard_task_runner.py:88} INFO - Job 45: Subtask task_3
[2024-04-24T09:35:42.743+0000] {task_command.py:423} INFO - Running <TaskInstance: use_case_dag.task_3 manual__2024-04-24T09:35:04.462838+00:00 [running]> on host 426889f50441
[2024-04-24T09:35:42.851+0000] {taskinstance.py:2513} INFO - Exporting env vars: AIRFLOW_CTX_DAG_OWNER='matteo' AIRFLOW_CTX_DAG_ID='use_case_dag' AIRFLOW_CTX_TASK_ID='task_3' AIRFLOW_CTX_EXECUTION_DATE='2024-04-24T09:35:04.462838+00:00' AIRFLOW_CTX_TRY_NUMBER='1' AIRFLOW_CTX_DAG_RUN_ID='manual__2024-04-24T09:35:04.462838+00:00'
[2024-04-24T09:35:52.549+0000] {taskinstance.py:2731} ERROR - Task failed with exception
Traceback (most recent call last):
  File "/home/airflow/.local/lib/python3.8/site-packages/airflow/models/taskinstance.py", line 444, in _execute_task
    result = _execute_callable(context=context, **execute_callable_kwargs)
  File "/home/airflow/.local/lib/python3.8/site-packages/airflow/models/taskinstance.py", line 414, in _execute_callable
    return execute_callable(context=context, **execute_callable_kwargs)
  File "/home/airflow/.local/lib/python3.8/site-packages/airflow/decorators/base.py", line 241, in execute
    return_value = super().execute(context)
  File "/home/airflow/.local/lib/python3.8/site-packages/airflow/operators/python.py", line 200, in execute
    return_value = self.execute_callable()
  File "/home/airflow/.local/lib/python3.8/site-packages/airflow/operators/python.py", line 217, in execute_callable
    return self.python_callable(*self.op_args, **self.op_kwargs)
  File "/opt/airflow/dags/use_case_dag.py", line 51, in task_3
    utils.get_best_countries(joined_data, best_recovery_countries)
  File "/opt/airflow/dags/utils.py", line 118, in get_best_countries
    best_recovery_countries = joined_df.select("location", "recovery_rate").orderBy(col("recovery_rate").desc()).limit(40)
  File "/home/airflow/.local/lib/python3.8/site-packages/pyspark/sql/dataframe.py", line 3227, in select
    jdf = self._jdf.select(self._jcols(*cols))
  File "/home/airflow/.local/lib/python3.8/site-packages/py4j/java_gateway.py", line 1322, in __call__
    return_value = get_return_value(
  File "/home/airflow/.local/lib/python3.8/site-packages/pyspark/errors/exceptions/captured.py", line 185, in deco
    raise converted from None
pyspark.errors.exceptions.captured.AnalysisException: [UNRESOLVED_COLUMN.WITH_SUGGESTION] A column or function parameter with name `location` cannot be resolved. Did you mean one of the following? [`_c0`, `_c1`, `_c10`, `_c2`, `_c3`].;
'Project ['location, 'recovery_rate]
+- Relation [_c0#17,_c1#18,_c2#19,_c3#20,_c4#21,_c5#22,_c6#23,_c7#24,_c8#25,_c9#26,_c10#27] csv

[2024-04-24T09:35:52.583+0000] {taskinstance.py:1149} INFO - Marking task as UP_FOR_RETRY. dag_id=use_case_dag, task_id=task_3, execution_date=20240424T093504, start_date=20240424T093542, end_date=20240424T093552
[2024-04-24T09:35:52.606+0000] {standard_task_runner.py:107} ERROR - Failed to execute job 45 for task task_3 ([UNRESOLVED_COLUMN.WITH_SUGGESTION] A column or function parameter with name `location` cannot be resolved. Did you mean one of the following? [`_c0`, `_c1`, `_c10`, `_c2`, `_c3`].;
'Project ['location, 'recovery_rate]
+- Relation [_c0#17,_c1#18,_c2#19,_c3#20,_c4#21,_c5#22,_c6#23,_c7#24,_c8#25,_c9#26,_c10#27] csv
; 8365)
[2024-04-24T09:35:52.638+0000] {local_task_job_runner.py:234} INFO - Task exited with return code 1
[2024-04-24T09:35:52.665+0000] {taskinstance.py:3312} INFO - 0 downstream tasks scheduled from follow-on schedule check
