[2024-04-24T09:59:19.676+0000] {taskinstance.py:1979} INFO - Dependencies all met for dep_context=non-requeueable deps ti=<TaskInstance: use_case_dag.task_3 manual__2024-04-24T09:37:53.666524+00:00 [queued]>
[2024-04-24T09:59:19.694+0000] {taskinstance.py:1979} INFO - Dependencies all met for dep_context=requeueable deps ti=<TaskInstance: use_case_dag.task_3 manual__2024-04-24T09:37:53.666524+00:00 [queued]>
[2024-04-24T09:59:19.695+0000] {taskinstance.py:2193} INFO - Starting attempt 3 of 8
[2024-04-24T09:59:19.719+0000] {taskinstance.py:2217} INFO - Executing <Task(_PythonDecoratedOperator): task_3> on 2024-04-24 09:37:53.666524+00:00
[2024-04-24T09:59:19.732+0000] {standard_task_runner.py:60} INFO - Started process 12195 to run task
[2024-04-24T09:59:19.738+0000] {standard_task_runner.py:87} INFO - Running: ['***', 'tasks', 'run', 'use_case_dag', 'task_3', 'manual__2024-04-24T09:37:53.666524+00:00', '--job-id', '65', '--raw', '--subdir', 'DAGS_FOLDER/use_case_dag.py', '--cfg-path', '/tmp/tmp36ylx91p']
[2024-04-24T09:59:19.744+0000] {standard_task_runner.py:88} INFO - Job 65: Subtask task_3
[2024-04-24T09:59:19.847+0000] {task_command.py:423} INFO - Running <TaskInstance: use_case_dag.task_3 manual__2024-04-24T09:37:53.666524+00:00 [running]> on host 426889f50441
[2024-04-24T09:59:19.972+0000] {taskinstance.py:2513} INFO - Exporting env vars: AIRFLOW_CTX_DAG_OWNER='matteo' AIRFLOW_CTX_DAG_ID='use_case_dag' AIRFLOW_CTX_TASK_ID='task_3' AIRFLOW_CTX_EXECUTION_DATE='2024-04-24T09:37:53.666524+00:00' AIRFLOW_CTX_TRY_NUMBER='3' AIRFLOW_CTX_DAG_RUN_ID='manual__2024-04-24T09:37:53.666524+00:00'
[2024-04-24T09:59:28.925+0000] {taskinstance.py:2731} ERROR - Task failed with exception
Traceback (most recent call last):
  File "/home/airflow/.local/lib/python3.8/site-packages/airflow/models/taskinstance.py", line 444, in _execute_task
    result = _execute_callable(context=context, **execute_callable_kwargs)
  File "/home/airflow/.local/lib/python3.8/site-packages/airflow/models/taskinstance.py", line 414, in _execute_callable
    return execute_callable(context=context, **execute_callable_kwargs)
  File "/home/airflow/.local/lib/python3.8/site-packages/airflow/decorators/base.py", line 241, in execute
    return_value = super().execute(context)
  File "/home/airflow/.local/lib/python3.8/site-packages/airflow/operators/python.py", line 200, in execute
    return_value = self.execute_callable()
  File "/home/airflow/.local/lib/python3.8/site-packages/airflow/operators/python.py", line 217, in execute_callable
    return self.python_callable(*self.op_args, **self.op_kwargs)
  File "/opt/airflow/dags/use_case_dag.py", line 51, in task_3
    utils.get_best_countries(joined_data, best_recovery_countries)
  File "/opt/airflow/dags/utils.py", line 120, in get_best_countries
    best_recovery_countries.mode('overwrite').write.csv('data/best_recovery_countries', header=True)
  File "/home/airflow/.local/lib/python3.8/site-packages/pyspark/sql/dataframe.py", line 3127, in __getattr__
    raise AttributeError(
AttributeError: 'DataFrame' object has no attribute 'mode'
[2024-04-24T09:59:28.943+0000] {taskinstance.py:1149} INFO - Marking task as UP_FOR_RETRY. dag_id=use_case_dag, task_id=task_3, execution_date=20240424T093753, start_date=20240424T095919, end_date=20240424T095928
[2024-04-24T09:59:28.966+0000] {standard_task_runner.py:107} ERROR - Failed to execute job 65 for task task_3 ('DataFrame' object has no attribute 'mode'; 12195)
[2024-04-24T09:59:28.998+0000] {local_task_job_runner.py:234} INFO - Task exited with return code 1
[2024-04-24T09:59:29.037+0000] {taskinstance.py:3312} INFO - 0 downstream tasks scheduled from follow-on schedule check
