[2024-04-24T09:59:58.329+0000] {taskinstance.py:1979} INFO - Dependencies all met for dep_context=non-requeueable deps ti=<TaskInstance: use_case_dag.task_3 manual__2024-04-24T09:59:19.488116+00:00 [queued]>
[2024-04-24T09:59:58.341+0000] {taskinstance.py:1979} INFO - Dependencies all met for dep_context=requeueable deps ti=<TaskInstance: use_case_dag.task_3 manual__2024-04-24T09:59:19.488116+00:00 [queued]>
[2024-04-24T09:59:58.342+0000] {taskinstance.py:2193} INFO - Starting attempt 1 of 6
[2024-04-24T09:59:58.358+0000] {taskinstance.py:2217} INFO - Executing <Task(_PythonDecoratedOperator): task_3> on 2024-04-24 09:59:19.488116+00:00
[2024-04-24T09:59:58.367+0000] {standard_task_runner.py:60} INFO - Started process 12745 to run task
[2024-04-24T09:59:58.372+0000] {standard_task_runner.py:87} INFO - Running: ['***', 'tasks', 'run', 'use_case_dag', 'task_3', 'manual__2024-04-24T09:59:19.488116+00:00', '--job-id', '68', '--raw', '--subdir', 'DAGS_FOLDER/use_case_dag.py', '--cfg-path', '/tmp/tmp72zqes2i']
[2024-04-24T09:59:58.377+0000] {standard_task_runner.py:88} INFO - Job 68: Subtask task_3
[2024-04-24T09:59:58.446+0000] {task_command.py:423} INFO - Running <TaskInstance: use_case_dag.task_3 manual__2024-04-24T09:59:19.488116+00:00 [running]> on host 426889f50441
[2024-04-24T09:59:58.553+0000] {taskinstance.py:2513} INFO - Exporting env vars: AIRFLOW_CTX_DAG_OWNER='matteo' AIRFLOW_CTX_DAG_ID='use_case_dag' AIRFLOW_CTX_TASK_ID='task_3' AIRFLOW_CTX_EXECUTION_DATE='2024-04-24T09:59:19.488116+00:00' AIRFLOW_CTX_TRY_NUMBER='1' AIRFLOW_CTX_DAG_RUN_ID='manual__2024-04-24T09:59:19.488116+00:00'
[2024-04-24T10:00:05.933+0000] {taskinstance.py:2731} ERROR - Task failed with exception
Traceback (most recent call last):
  File "/home/airflow/.local/lib/python3.8/site-packages/airflow/models/taskinstance.py", line 444, in _execute_task
    result = _execute_callable(context=context, **execute_callable_kwargs)
  File "/home/airflow/.local/lib/python3.8/site-packages/airflow/models/taskinstance.py", line 414, in _execute_callable
    return execute_callable(context=context, **execute_callable_kwargs)
  File "/home/airflow/.local/lib/python3.8/site-packages/airflow/decorators/base.py", line 241, in execute
    return_value = super().execute(context)
  File "/home/airflow/.local/lib/python3.8/site-packages/airflow/operators/python.py", line 200, in execute
    return_value = self.execute_callable()
  File "/home/airflow/.local/lib/python3.8/site-packages/airflow/operators/python.py", line 217, in execute_callable
    return self.python_callable(*self.op_args, **self.op_kwargs)
  File "/opt/airflow/dags/use_case_dag.py", line 51, in task_3
    utils.get_best_countries(joined_data, best_recovery_countries)
  File "/opt/airflow/dags/utils.py", line 120, in get_best_countries
    best_recovery_countries.mode('overwrite').write.csv('data/best_recovery_countries', header=True)
  File "/home/airflow/.local/lib/python3.8/site-packages/pyspark/sql/dataframe.py", line 3127, in __getattr__
    raise AttributeError(
AttributeError: 'DataFrame' object has no attribute 'mode'
[2024-04-24T10:00:05.947+0000] {taskinstance.py:1149} INFO - Marking task as UP_FOR_RETRY. dag_id=use_case_dag, task_id=task_3, execution_date=20240424T095919, start_date=20240424T095958, end_date=20240424T100005
[2024-04-24T10:00:05.965+0000] {standard_task_runner.py:107} ERROR - Failed to execute job 68 for task task_3 ('DataFrame' object has no attribute 'mode'; 12745)
[2024-04-24T10:00:06.015+0000] {local_task_job_runner.py:234} INFO - Task exited with return code 1
[2024-04-24T10:00:06.037+0000] {taskinstance.py:3312} INFO - 0 downstream tasks scheduled from follow-on schedule check
