[2024-04-24T08:39:04.078+0000] {taskinstance.py:1979} INFO - Dependencies all met for dep_context=non-requeueable deps ti=<TaskInstance: use_case_dag.task_1 manual__2024-04-24T08:39:01.399932+00:00 [queued]>
[2024-04-24T08:39:04.086+0000] {taskinstance.py:1979} INFO - Dependencies all met for dep_context=requeueable deps ti=<TaskInstance: use_case_dag.task_1 manual__2024-04-24T08:39:01.399932+00:00 [queued]>
[2024-04-24T08:39:04.087+0000] {taskinstance.py:2193} INFO - Starting attempt 1 of 6
[2024-04-24T08:39:04.098+0000] {taskinstance.py:2217} INFO - Executing <Task(_PythonDecoratedOperator): task_1> on 2024-04-24 08:39:01.399932+00:00
[2024-04-24T08:39:04.104+0000] {standard_task_runner.py:60} INFO - Started process 261 to run task
[2024-04-24T08:39:04.107+0000] {standard_task_runner.py:87} INFO - Running: ['***', 'tasks', 'run', 'use_case_dag', 'task_1', 'manual__2024-04-24T08:39:01.399932+00:00', '--job-id', '3', '--raw', '--subdir', 'DAGS_FOLDER/use_case_dag.py', '--cfg-path', '/tmp/tmp_gprbcbe']
[2024-04-24T08:39:04.110+0000] {standard_task_runner.py:88} INFO - Job 3: Subtask task_1
[2024-04-24T08:39:04.165+0000] {task_command.py:423} INFO - Running <TaskInstance: use_case_dag.task_1 manual__2024-04-24T08:39:01.399932+00:00 [running]> on host 426889f50441
[2024-04-24T08:39:04.240+0000] {taskinstance.py:2513} INFO - Exporting env vars: AIRFLOW_CTX_DAG_OWNER='matteo' AIRFLOW_CTX_DAG_ID='use_case_dag' AIRFLOW_CTX_TASK_ID='task_1' AIRFLOW_CTX_EXECUTION_DATE='2024-04-24T08:39:01.399932+00:00' AIRFLOW_CTX_TRY_NUMBER='1' AIRFLOW_CTX_DAG_RUN_ID='manual__2024-04-24T08:39:01.399932+00:00'
[2024-04-24T08:39:14.663+0000] {taskinstance.py:2731} ERROR - Task failed with exception
Traceback (most recent call last):
  File "/home/airflow/.local/lib/python3.8/site-packages/airflow/models/taskinstance.py", line 444, in _execute_task
    result = _execute_callable(context=context, **execute_callable_kwargs)
  File "/home/airflow/.local/lib/python3.8/site-packages/airflow/models/taskinstance.py", line 414, in _execute_callable
    return execute_callable(context=context, **execute_callable_kwargs)
  File "/home/airflow/.local/lib/python3.8/site-packages/airflow/decorators/base.py", line 241, in execute
    return_value = super().execute(context)
  File "/home/airflow/.local/lib/python3.8/site-packages/airflow/operators/python.py", line 200, in execute
    return_value = self.execute_callable()
  File "/home/airflow/.local/lib/python3.8/site-packages/airflow/operators/python.py", line 217, in execute_callable
    return self.python_callable(*self.op_args, **self.op_kwargs)
  File "/opt/airflow/dags/use_case_dag.py", line 36, in task_1
    utils.transform_owid_data(large_covid_data, transformed_owid_covid_data)
  File "/opt/airflow/dags/utils.py", line 28, in transform_owid_data
    owid_covid_agg.write.mode('append').parquet(transformed_owid_covid_data['path'])
TypeError: 'DataCollection' object is not subscriptable
[2024-04-24T08:39:14.674+0000] {taskinstance.py:1149} INFO - Marking task as UP_FOR_RETRY. dag_id=use_case_dag, task_id=task_1, execution_date=20240424T083901, start_date=20240424T083904, end_date=20240424T083914
[2024-04-24T08:39:14.688+0000] {standard_task_runner.py:107} ERROR - Failed to execute job 3 for task task_1 ('DataCollection' object is not subscriptable; 261)
[2024-04-24T08:39:14.703+0000] {local_task_job_runner.py:234} INFO - Task exited with return code 1
[2024-04-24T08:39:14.725+0000] {taskinstance.py:3312} INFO - 0 downstream tasks scheduled from follow-on schedule check
